Workbook

Sheet Detallado de Facturacion1
A1: CUFE | B1: Cliente | C1: Cuenta | D1: Producto | E1: NIC | F1: NIS | G1: Identificación | H1: Nombres | I1: direccion | J1: barrio | K1: Planilla | L1: Grupo empresarial | M1: Nombre Municipio | N1: Cod. Localidad | O1: Ciclo de consumo | P1: Plan de facturación | Q1: Categoría | R1: Subcategoría | S1: Método de análisis | T1: Estado | U1: Año | V1: Mes(es) | W1: Factura | X1: Cuenta de cobro | Y1: Generada el | Z1: Vence el | AA1: Total Cuenta | AB1: Monto facturado | AC1: Subsidio y/o Contribuciones | AD1: Consumo | AE1: VALOR INGRESOS INTERESES | AF1: Valor De Financiaciones | AG1: Cuota | AH1: Interes Financiacion | AI1: TOTAL IMPUESTO | AJ1: Saldo pendiente | AK1: Deuda Total | AL1: Cuentas Vencidas | AM1: Valor_Otros | AN1: Valor Nota | AO1: Valor Movimiento SA | AP1: Valor de pago | AQ1: Valor Movimiento AS | AR1: Fecha de Pago | AS1: CORREO | AT1: MEDIO DE ENVIO | AU1: responsable | AV1: FECHA | AW1: RESPONSABLE
A2: 350df86281db5b15694e51b476565ff1883fd89dc00e172004c6f770c11448e7126108f0fa80511e760eb5424a0a844b | B2: 2744 | C2: 2743 | D2: 2743 | E2: 90256510 | F2: 90256510 | G2: 800099262 | H2: ALCALDIA MUNICIPIO DE SANTIAGO | I2: =VLOOKUP(C2,'mayo-26'!B:H,7,0) -> CARRERA 3 NO. 2-31 | J2: 0 | K2: DF | L2: DF | M2: CÚCUTA MPO | N2: CUCUTA ZONA SUR | O2: 1001 - CICL FACT PARQUE GUAYABAL( 63) | P2: DIS. FINAL Y TRATAMIENTO | Q2: NO RESIDENCIAL - ASEO GP | R2: OFICIAL | S2: AFORO PERMANENTE | T2: Ocupado | U2: 2026 | V2: 6 | W2: 1081874793 | X2: 1081893265 | Y2: 09-06-2026 | Z2: 04-07-2026 | AA2: 824660.64 | AB2: 824660.64 | AC2: 0 | AD2: 17540 | AE2: 0 | AF2: 0 | AG2: 0 | AH2: 0 | AI2: 0 | AJ2: 824660.64 | AK2: 824660.64 | AL2: 0 | AM2: 240385.7 | AN2: 0 | AS2: =VLOOKUP(C2,'mayo-26'!B:AS,44,0) -> TESORERIA@SANTIAGO-NORTEDESANTANDER.GOV.CO | AT2: =VLOOKUP(C2,'mayo-26'!B:AT,45,0) -> CORREO ELECTRONICO CERTIFICADO 472
A3: caf805b515e6ebda323b20de9bf89e5d6848708156d0478096975ead5363d5490a44564c25edabc3291e63adea01ceca | B3: 2748 | C3: 2747 | D3: 2747 | E3: 90256652 | F3: 90256652 | G3: 890503483-2 | H3: ALCALDIA BUCARASICA | I3: =VLOOKUP(C3,'mayo-26'!B:H,7,0) -> CALLE 2 NO. 3-35 | J3: 0 | K3: DF | L3: DF | M3: CÚCUTA MPO | N3: CUCUTA ZONA SUR | O3: 1001 - CICL FACT PARQUE GUAYABAL( 63) | P3: DIS. FINAL Y TRATAMIENTO | Q3: NO RESIDENCIAL - ASEO GP | R3: OFICIAL | S3: AFORO PERMANENTE | T3: Ocupado | U3: 2026 | V3: 6 | W3: 1081874797 | X3: 1081893269 | Y3: 09-06-2026 | Z3: 04-07-2026 | AA3: 893774.16 | AB3: 893774.16 | AC3: 0 | AD3: 19010 | AE3: 0 | AF3: 0 | AG3: 0 | AH3: 0 | AI3: 0 | AJ3: 893774.16 | AK3: 893774.16 | AL3: 0 | AM3: 260532.05 | AN3: 0 | AS3: =VLOOKUP(C3,'mayo-26'!B:AS,44,0) -> HACIENDA@BUCARASICA-NORTEDESANTANDER.GOV.CO | AT3: =VLOOKUP(C3,'mayo-26'!B:AT,45,0) -> CORREO ELECTRONICO CERTIFICADO 472
A4: d65219d66c87f03199cc557f5fba79ae46e40e729068fa919d87434013c8e038ed20f5bf89db573c8862fd1b67e0b970 | B4: 2752 | C4: 2751 | D4: 2751 | E4: 90257710 | F4: 90257710 | G4: 890501876 | H4: MUNICIPIO DE SAN CAYETANO | I4: =VLOOKUP(C4,'mayo-26'!B:H,7,0) -> CARRERA 4 N 3 -61 | J4: 0 | K4: DF | L4: DF | M4: CÚCUTA MPO | N4: CUCUTA ZONA SUR | O4: 1001 - CICL FACT PARQUE GUAYABAL( 63) | P4: DIS. FINAL Y TRATAMIENTO | Q4: NO RESIDENCIAL - ASEO GP | R4: OFICIAL | S4: AFORO PERMANENTE | T4: Ocupado | U4: 2026 | V4: 6 | W4: 1081874799 | X4: 1081893271 | Y4: 09-06-2026 | Z4: 04-07-2026 | AA4: 5626874.9 | AB4: 5626874.9 | AC4: 0 | AD4: 119680 | AE4: 0 | AF4: 0 | AG4: 0 | AH4: 0 | AI4: 0 | AJ4: 5626874.9 | AK4: 10986409 | AL4: 1 | AM4: 1640214.4 | AN4: 0 | AS4: =VLOOKUP(C4,'mayo-26'!B:AS,44,0) -> tesoreria@sancayetano-nortedesantander.gov.co | AT4: =VLOOKUP(C4,'mayo-26'!B:AT,45,0) -> CORREO ELECTRONICO CERTIFICADO 472
A5: cd658a72087c9a44a952156917330b59bde2aef8590acec5041a0f6871c62d6c535bab7c78b3360e475a5c94ed117c37 | B5: 2760 | C5: 2759 | D5: 2759 | E5: 90290491 | F5: 90290491 | G5: 901238264-9 | H5: ADM PUB SERV PUBL DOMICILIA ACU ALC ASEO | I5: =VLOOKUP(C5,'mayo-26'!B:H,7,0) -> CRA 5 6-03 BARR PERPETUO SOCORRO | J5: HERRAN | K5: DF | L5: DF | M5: CÚCUTA MPO | N5: CUCUTA ZONA SUR | O5: 1001 - CICL FACT PARQUE GUAYABAL( 63) | P5: DIS. FINAL Y TRATAMIENTO | Q5: NO RESIDENCIAL - ASEO GP | R5: INDUSTRIAL | S5: AFORO PERMANENTE | T5: Ocupado | U5: 2026 | V5: 6 | W5: 1081874802 | X5: 1081893274 | Y5: 09-06-2026 | Z5: 04-07-2026 | AA5: 489906.72 | AB5: 489906.72 | AC5: 0 | AD5: 10420 | AE5: 0 | AF5: 0 | AG5: 0 | AH5: 0 | AI5: 0 | AJ5: 489906.34 | AK5: 489906.34 | AL5: 0 | AM5: 142806.1 | AN5: 0 | AQ5: 0.38 | AS5: =VLOOKUP(C5,'mayo-26'!B:AS,44,0) -> APCMANOBAHERRAN@GMAIL.COM | AT5: =VLOOKUP(C5,'mayo-26'!B:AT,45,0) -> CORREO ELECTRONICO CERTIFICADO 472
A6: f07e386cc5fce54c23b35dbad28c861238398ee1e12f526fb84c13c35166b320361f8694e9e08c48fe112da98121e05b | B6: 584 | C6: 583 | D6: 583 | E6: 90275668 | F6: 90275668 | G6: 807005252-1 | H6: ECOAMBIENTAL DEL NORTE SAS ESP | I6: =VLOOKUP(C6,'mayo-26'!B:H,7,0) -> CARRERA 7 NO. 3-17 VILLA DEL ROSARIO | J6: SIN DETERMINAR | K6: DF | L6: DF | M6: CÚCUTA MPO | N6: CUCUTA ZONA SUR | O6: 1001 - CICL FACT PARQUE GUAYABAL( 63) | P6: DIS. FINAL Y TRATAMIENTO | Q6: NO RESIDENCIAL - ASEO GP | R6: INDUSTRIAL | S6: AFORO PERMANENTE | T6: Ocupado | U6: 2026 | V6: 6 | W6: 1081874780 | X6: 1081893252 | Y6: 09-06-2026 | Z6: 04-07-2026 | AA6: 10112318 | AB6: 10112318 | AC6: 0 | AD6: 212630 | AE6: 115306.31 | AF6: 0 | AG6: 0 | AH6: 0 | AI6: 0 | AJ6: 10112318 | AK6: 20433676 | AL6: 1 | AM6: 2914094.1 | AN6: 0 | AS6: =VLOOKUP(C6,'mayo-26'!B:AS,44,0) -> ecoambiental807@gmail.com | AT6: =VLOOKUP(C6,'mayo-26'!B:AT,45,0) -> CORREO ELECTRONICO CERTIFICADO 472
A7: fcece3941ddce843aa2003dfeeea1eb9cd2889a0d0b253358d4cf29fd5f671f7cbe70a13a1d94889f76dcb877ec31627 | B7: 2742 | C7: 2741 | D7: 2741 | E7: 90254686 | F7: 90254686 | G7: 807000581-5 | H7: EMPRESAS PUBLICAS MUNICIPALES DE CHINACOTA EMCHINAC | I7: =VLOOKUP(C7,'mayo-26'!B:H,7,0) -> CRA 4A 13-35 BARRIO LAS COLINAS/CHINACOTA | J7: 0 | K7: DF | L7: DF | M7: CÚCUTA MPO | N7: CUCUTA ZONA SUR | O7: 1001 - CICL FACT PARQUE GUAYABAL( 63) | P7: DIS. FINAL Y TRATAMIENTO | Q7: NO RESIDENCIAL - ASEO GP | R7: INDUSTRIAL | S7: AFORO PERMANENTE | T7: Ocupado | U7: 2026 | V7: 6 | W7: 1081874776 | X7: 1081893248 | Y7: 09-06-2026 | Z7: 04-07-2026 | AA7: 12467233 | AB7: 12467233 | AC7: 0 | AD7: 265170 | AE7: 0 | AF7: 0 | AG7: 0 | AH7: 0 | AI7: 0 | AJ7: 12467233 | AK7: 12467233 | AL7: 1 | AM7: 3634154.9 | AN7: 0 | AS7: =VLOOKUP(C7,'mayo-26'!B:AS,44,0) -> EMCHINAC@EMCHINACESP-CHINACOTA.GOV.CO | AT7: =VLOOKUP(C7,'mayo-26'!B:AT,45,0) -> CORREO ELECTRONICO CERTIFICADO 472
A8: 5840f4487b33aa9217b5f28a2ef480ab059183617a9ff3e113865ffb2155b4a606c468f4eb9b06796a39d4a2f2b7f48c | B8: 2746 | C8: 2745 | D8: 2745 | E8: 90256586 | F8: 90256586 | G8: 800099251 | H8: ALCALDIA MUNICIPIO RAGONVALIA | I8: =VLOOKUP(C8,'mayo-26'!B:H,7,0) -> CALLE 6 NO. 2-32 | J8: 0 | K8: DF | L8: DF | M8: CÚCUTA MPO | N8: CUCUTA ZONA SUR | O8: 1001 - CICL FACT PARQUE GUAYABAL( 63) | P8: DIS. FINAL Y TRATAMIENTO | Q8: NO RESIDENCIAL - ASEO GP | R8: OFICIAL | S8: AFORO PERMANENTE | T8: Ocupado | U8: 2026 | V8: 6 | W8: 1081874779 | X8: 1081893251 | Y8: 09-06-2026 | Z8: 04-07-2026 | AA8: 1619231 | AB8: 1619231 | AC8: 0 | AD8: 34440 | AE8: 0 | AF8: 0 | AG8: 0 | AH8: 0 | AI8: 0 | AJ8: 1619231 | AK8: 1619231 | AL8: 0 | AM8: 472000.2 | AN8: 0 | AS8: =VLOOKUP(C8,'mayo-26'!B:AS,44,0) -> HACIENDA@RAGONVALIA-NORTEDESANTANDER.GOV.CO | AT8: =VLOOKUP(C8,'mayo-26'!B:AT,45,0) -> CORREO ELECTRONICO CERTIFICADO 472
A9: fbf1c2dd1c3bb63cfeb263fc2cffdfff24223ebb0853cb1c2f7cbb1163ee8e8160070b275578760e9f52b9dd9b950d2c | B9: 2750 | C9: 2749 | D9: 2749 | E9: 90257708 | F9: 90257708 | G9: 890501981 | H9: MUNICIPIO DE VILLA CARO | I9: =VLOOKUP(C9,'mayo-26'!B:H,7,0) -> PALACIO MPAL VILLA CARO | J9: 0 | K9: DF | L9: DF | M9: CÚCUTA MPO | N9: CUCUTA ZONA SUR | O9: 1001 - CICL FACT PARQUE GUAYABAL( 63) | P9: DIS. FINAL Y TRATAMIENTO | Q9: NO RESIDENCIAL - ASEO GP | R9: OFICIAL | S9: AFORO PERMANENTE | T9: Ocupado | U9: 2026 | V9: 6 | W9: 1081874783 | X9: 1081893255 | Y9: 09-06-2026 | Z9: 04-07-2026 | AA9: 776704.32 | AB9: 776704.32 | AC9: 0 | AD9: 16520 | AE9: 0 | AF9: 0 | AG9: 0 | AH9: 0 | AI9: 0 | AJ9: 776704.32 | AK9: 776704.32 | AL9: 0 | AM9: 226406.6 | AN9: 0 | AS9: =VLOOKUP(C9,'mayo-26'!B:AS,44,0) -> tesoreria@villacaro-nortedesantander.gov.co | AT9: =VLOOKUP(C9,'mayo-26'!B:AT,45,0) -> CORREO ELECTRONICO CERTIFICADO 472
A10: 0ab2cea0dd7008f7b0b898e92f500160638cd18857df01a188e6a854b4c087b2a06cc73bbe6552c4d83cf637474868cb | B10: 2758 | C10: 2757 | D10: 2757 | E10: 90267356 | F10: 90267356 | G10: 890501436-7 | H10: ALCALDIA MUNICIPIO DE ARBOLEDAS | I10: =VLOOKUP(C10,'mayo-26'!B:H,7,0) -> CRA 6 CALLE 2 Y 3 NO 6-25 | J10: 0 | K10: DF | L10: DF | M10: CÚCUTA MPO | N10: CUCUTA ZONA SUR | O10: 1001 - CICL FACT PARQUE GUAYABAL( 63) | P10: DIS. FINAL Y TRATAMIENTO | Q10: NO RESIDENCIAL - ASEO GP | R10: OFICIAL | S10: AFORO PERMANENTE | T10: Ocupado | U10: 2026 | V10: 6 | W10: 1081874788 | X10: 1081893260 | Y10: 09-06-2026 | Z10: 04-07-2026 | AA10: 2356441.9 | AB10: 2356441.9 | AC10: 0 | AD10: 50120 | AE10: 0 | AF10: 0 | AG10: 0 | AH10: 0 | AI10: 0 | AJ10: 2356441.9 | AK10: 2356441.9 | AL10: 0 | AM10: 686894.6 | AN10: 0 | AS10: =VLOOKUP(C10,'mayo-26'!B:AS,44,0) -> tesoreria@arboledas-nortedesantander.gov.co | AT10: =VLOOKUP(C10,'mayo-26'!B:AT,45,0) -> CORREO ELECTRONICO CERTIFICADO 472
A11: e44282796a22a3c031e66db5d49fe2c2fae784aa87e9b7f851586321afb70780dd45a9a5d2bd597ebe3a17aa637ebf16 | B11: 608069 | C11: 502777 | D11: 558548 | G11: 900508526 | H11: EMPRESA DE SOLUCIONES AMBIENTALES PARA COLOMBIA S.A.S E.S.P | I11: =VLOOKUP(C11,'mayo-26'!B:H,7,0) -> KM 7 VDA EL CUCHARO | J11: #N/A | K11: DF | L11: DF | M11: CÚCUTA MPO | N11: CUCUTA DIRECTA | O11: 1001 - CICL FACT PARQUE GUAYABAL( 63) | P11: DIS. FINAL Y TRATAMIENTO | Q11: NO RESIDENCIAL - ASEO GP | R11: COMERCIAL | S11: AFORO PERMANENTE | T11: Ocupado | U11: 2026 | V11: 6 | W11: 1081874792 | X11: 1081893264 | Y11: 09-06-2026 | Z11: 04-07-2026 | AA11: 2611997.4 | AB11: 2611997.4 | AC11: 0 | AD11: 61550 | AE11: 0 | AF11: 0 | AG11: 0 | AH11: 0 | AI11: 0 | AJ11: 2611997.4 | AK11: 2611997.4 | AL11: 0 | AM11: 561705.3 | AN11: 0 | AS11: =VLOOKUP(C11,'mayo-26'!B:AS,44,0) -> empsacol@hotmail.com | AT11: =VLOOKUP(C11,'mayo-26'!B:AT,45,0) -> CORREO ELECTRONICO CERTIFICADO 472
A12: 03e674c3056d416774e2ee5cf3966d4982ed57b24cce717c28350fa3f6b4641c6ab917ada2a71b881deba56073c44fb9 | B12: 602 | C12: 601 | D12: 601 | E12: 90280179 | F12: 90280179 | G12: 13502903 | H12: PUBLICIDAD RINCON | I12: =VLOOKUP(C12,'mayo-26'!B:H,7,0) -> #N/A | J12: #N/A | K12: DF | L12: DF | M12: CÚCUTA MPO | N12: CUCUTA DIRECTA | O12: 1001 - CICL FACT PARQUE GUAYABAL( 63) | P12: DIS. FINAL Y TRATAMIENTO | Q12: NO RESIDENCIAL - ASEO GP | R12: INDUSTRIAL | S12: AFORO PERMANENTE | T12: Ocupado | U12: 2026 | V12: 6 | W12: 1081874773 | X12: 1081893245 | Y12: 09-06-2026 | Z12: 04-07-2026 | AA12: 36495.82 | AB12: 36495.82 | AC12: 0 | AD12: 860 | AE12: 0 | AF12: 0 | AG12: 0 | AH12: 0 | AI12: 0 | AJ12: 36495.82 | AK12: 36495.82 | AL12: 0 | AM12: 7848.36 | AN12: 0 | AS12: =VLOOKUP(C12,'mayo-26'!B:AS,44,0) -> #N/A | AT12: =VLOOKUP(C12,'mayo-26'!B:AT,45,0) -> #N/A
A13: c396fc8fd75811e249bce7f4846ef20d946210752706e77ced56579fda73abe24803f727f135fbcd50c535f34731d3e3 | B13: 2743 | C13: 2742 | D13: 2742 | E13: 90255897 | F13: 90255897 | G13: 890506116-8 | H13: ALCALDIA PAMPLONITA | I13: =VLOOKUP(C13,'mayo-26'!B:H,7,0) -> #N/A | J13: PAMPLONITA | K13: DF | L13: DF | M13: CÚCUTA MPO | N13: CUCUTA ZONA SUR | O13: 1001 - CICL FACT PARQUE GUAYABAL( 63) | P13: DIS. FINAL Y TRATAMIENTO | Q13: NO RESIDENCIAL - ASEO GP | R13: OFICIAL | S13: AFORO PERMANENTE | T13: Ocupado | U13: 2026 | V13: 6 | W13: 1081874778 | X13: 1081893250 | Y13: 09-06-2026 | Z13: 04-07-2026 | AA13: 279275.04 | AB13: 279275.04 | AC13: 0 | AD13: 5940 | AE13: 0 | AF13: 0 | AG13: 0 | AH13: 0 | AI13: 0 | AJ13: 279275.04 | AK13: 279275.04 | AL13: 0 | AM13: 81407.7 | AN13: 0 | AS13: =VLOOKUP(C13,'mayo-26'!B:AS,44,0) -> serviciospublicos@pamplonita-nortedesantander.gov.co | AT13: =VLOOKUP(C13,'mayo-26'!B:AT,45,0) -> CORREO ELECTRONICO CERTIFICADO 472
A14: bbc396954ae12cd5a12e4232596af9e097d3c4dc4da740d6a7acd7d8831bf3b1352cea3f9b5f830138cbc4e4490ad08e | B14: 2747 | C14: 2746 | D14: 2746 | E14: 90256627 | F14: 90256627 | G14: 800099237 | H14: EMPODURANIA | I14: =VLOOKUP(C14,'mayo-26'!B:H,7,0) -> AVENIDA 2 NO. 8-57 | J14: 0 | K14: DF | L14: DF | M14: CÚCUTA MPO | N14: CUCUTA ZONA SUR | O14: 1001 - CICL FACT PARQUE GUAYABAL( 63) | P14: DIS. FINAL Y TRATAMIENTO | Q14: NO RESIDENCIAL - ASEO GP | R14: INDUSTRIAL | S14: AFORO PERMANENTE | T14: Ocupado | U14: 2026 | V14: 6 | W14: 1081874781 | X14: 1081893253 | Y14: 09-06-2026 | Z14: 04-07-2026 | AA14: 2183423 | AB14: 2183423 | AC14: 0 | AD14: 46440 | AE14: 0 | AF14: 0 | AG14: 0 | AH14: 0 | AI14: 0 | AJ14: 105592.04 | AK14: 105592.04 | AL14: 0 | AM14: 636460.2 | AN14: 0 | AQ14: 2077831 | AS14: =VLOOKUP(C14,'mayo-26'!B:AS,44,0) -> CONTACTENOS@DURANIA-NORTEDESANTANDER.GOV.CO | AT14: =VLOOKUP(C14,'mayo-26'!B:AT,45,0) -> CORREO ELECTRONICO CERTIFICADO 472
A15: 033afab33dd33beba8a8b4700f911794905b7b5f5829644e8df048261057d6fbcf86eb7fba6c644b072ea45c6388fafb | B15: 2751 | C15: 2750 | D15: 2750 | E15: 90257709 | F15: 90257709 | G15: 890501404 | H15: MUNICIPIO DE GRAMALOTE | I15: =VLOOKUP(C15,'mayo-26'!B:H,7,0) -> CARRERA 5 NO 7 ¿ 72 | J15: 0 | K15: DF | L15: DF | M15: CÚCUTA MPO | N15: CUCUTA ZONA SUR | O15: 1001 - CICL FACT PARQUE GUAYABAL( 63) | P15: DIS. FINAL Y TRATAMIENTO | Q15: NO RESIDENCIAL - ASEO GP | R15: OFICIAL | S15: AFORO PERMANENTE | T15: Ocupado | U15: 2026 | V15: 6 | W15: 1081874785 | X15: 1081893257 | Y15: 09-06-2026 | Z15: 04-07-2026 | AA15: 2156153.8 | AB15: 2156153.8 | AC15: 0 | AD15: 45860 | AE15: 0 | AF15: 0 | AG15: 0 | AH15: 0 | AI15: 0 | AJ15: 2156153.8 | AK15: 2156153.8 | AL15: 0 | AM15: 628511.3 | AN15: 0 | AS15: =VLOOKUP(C15,'mayo-26'!B:AS,44,0) -> TESORERIA@GRAMALOTE-NORTEDESANTANDER.GOV.CO | AT15: =VLOOKUP(C15,'mayo-26'!B:AT,45,0) -> CORREO ELECTRONICO CERTIFICADO 472
A16: 0697dffc97c87f25ba397afcd4c5ea4c6477c7e2a14c377a6ba26bb2e3925da64815ec4abf1d222ec98c718a20c6514e | B16: 2755 | C16: 2754 | D16: 2754 | E16: 90257713 | F16: 90257713 | G16: 890502611 | H16: MUNICIPIO DE LOURDES | I16: =VLOOKUP(C16,'mayo-26'!B:H,7,0) -> CARRERA 4 CON CALLE 3 ¿ 36 | J16: 0 | K16: DF | L16: DF | M16: CÚCUTA MPO | N16: CUCUTA ZONA SUR | O16: 1001 - CICL FACT PARQUE GUAYABAL( 63) | P16: DIS. FINAL Y TRATAMIENTO | Q16: NO RESIDENCIAL - ASEO GP | R16: OFICIAL | S16: AFORO PERMANENTE | T16: Ocupado | U16: 2026 | V16: 6 | W16: 1081874789 | X16: 1081893261 | Y16: 09-06-2026 | Z16: 04-07-2026 | AA16: 2158974.7 | AB16: 2158974.7 | AC16: 0 | AD16: 45920 | AE16: 0 | AF16: 0 | AG16: 0 | AH16: 0 | AI16: 0 | AJ16: 2158974.7 | AK16: 2158974.7 | AL16: 0 | AM16: 629333.6 | AN16: 0 | AS16: =VLOOKUP(C16,'mayo-26'!B:AS,44,0) -> TESORERIA@LOURDES-NORTEDESANTANDER.GOV.CO | AT16: =VLOOKUP(C16,'mayo-26'!B:AT,45,0) -> CORREO ELECTRONICO CERTIFICADO 472
A17: ba0e1392a34c56a913f413bf4ed1e71c2ca2658a83c03ed5586fca35d46e5320961a354840cc60e4715478392c0d733b | B17: 2293 | C17: 2292 | D17: 2292 | E17: 90265701 | F17: 90265701 | G17: 890501301-1 | H17: SOCIEDAD MEJORAS PUBLICAS DE CUCUTA | I17: =VLOOKUP(C17,'mayo-26'!B:H,7,0) -> CALLE 4AN # 4-89 PESCADERO | J17: PESCADERO | K17: DF | L17: DF | M17: CÚCUTA MPO | N17: CUCUTA DIRECTA | O17: 1001 - CICL FACT PARQUE GUAYABAL( 63) | P17: DIS. FINAL Y TRATAMIENTO | Q17: NO RESIDENCIAL - ASEO GP | R17: INDUSTRIAL | S17: AFORO PERMANENTE | T17: Ocupado | U17: 2026 | V17: 6 | W17: 1081874784 | X17: 1081893256 | Y17: 09-06-2026 | Z17: 04-07-2026 | AA17: 3055888.4 | AB17: 3055888.4 | AC17: 0 | AD17: 72010 | AE17: 0 | AF17: 0 | AG17: 0 | AH17: 0 | AI17: 0 | AJ17: 3055888.4 | AK17: 3055888.4 | AL17: 0 | AM17: 657163.26 | AN17: 0 | AS17: =VLOOKUP(C17,'mayo-26'!B:AS,44,0) -> contacto@smpcucuta.com | AT17: =VLOOKUP(C17,'mayo-26'!B:AT,45,0) -> CORREO ELECTRONICO CERTIFICADO 472
A18: 40e7d18a76330c0d03c5b075533c401d73e2e3b7d02e458b9b702b2ab10f0b8a9343853801ff0acdf7b86e8c20af0ae6 | B18: 2741 | C18: 2740 | D18: 2740 | E18: 90253728 | F18: 90253728 | G18: 800250853-1 | H18: ALCALDIA MUNICIPAL PUERTO SANT | I18: =VLOOKUP(C18,'mayo-26'!B:H,7,0) -> CARERA 2 NO. 2-35 | J18: 0 | K18: DF | L18: DF | M18: CÚCUTA MPO | N18: CUCUTA ZONA SUR | O18: 1001 - CICL FACT PARQUE GUAYABAL( 63) | P18: DIS. FINAL Y TRATAMIENTO | Q18: NO RESIDENCIAL - ASEO GP | R18: OFICIAL | S18: AFORO PERMANENTE | T18: Ocupado | U18: 2026 | V18: 6 | W18: 1081874786 | X18: 1081893258 | Y18: 09-06-2026 | Z18: 04-07-2026 | AA18: 4691256.5 | AB18: 4691256.5 | AC18: 0 | AD18: 99780 | AE18: 0 | AF18: 0 | AG18: 0 | AH18: 0 | AI18: 0 | AJ18: 4691256.5 | AK18: 4691256.5 | AL18: 0 | AM18: 1367484.9 | AN18: 0 | AS18: =VLOOKUP(C18,'mayo-26'!B:AS,44,0) -> TESORERIA@PUERTOSANTANDER-NORTEDESANTANDER.GOV.CO | AT18: =VLOOKUP(C18,'mayo-26'!B:AT,45,0) -> CORREO ELECTRONICO CERTIFICADO 472
A19: 511cc5f8215fbac624389cbc6be81486fd02b113fbb5ee5cc52d18ea4b450c5a667379322d02c4970f692d93114d51fa | B19: 2745 | C19: 2744 | D19: 2744 | E19: 90256525 | F19: 90256525 | G19: 800099263-8 | H19: MUNICIPIO DE SARDINATA | I19: =VLOOKUP(C19,'mayo-26'!B:H,7,0) -> CALLE 6 NO. 6 55 CENTRO SARDINATA | J19: 0 | K19: DF | L19: DF | M19: CÚCUTA MPO | N19: CUCUTA ZONA SUR | O19: 1001 - CICL FACT PARQUE GUAYABAL( 63) | P19: DIS. FINAL Y TRATAMIENTO | Q19: NO RESIDENCIAL - ASEO GP | R19: OFICIAL | S19: AFORO PERMANENTE | T19: Ocupado | U19: 2026 | V19: 6 | W19: 1081874791 | X19: 1081893263 | Y19: 09-06-2026 | Z19: 04-07-2026 | AA19: 11533965 | AB19: 11533965 | AC19: 0 | AD19: 245320 | AE19: 0 | AF19: 0 | AG19: 0 | AH19: 0 | AI19: 0 | AJ19: 11533965 | AK19: 11533965 | AL19: 0 | AM19: 3362110.6 | AN19: 0 | AS19: =VLOOKUP(C19,'mayo-26'!B:AS,44,0) | AT19: =VLOOKUP(C19,'mayo-26'!B:AT,45,0) -> CORREO ELECTRONICO CERTIFICADO 472
A20: 9e0f72d6ac1ca8dea3e73c892ea804001cd75eb41d2bf51dd9dc345e3baff3e40d17cc767e94091784f9b0d6b688a388 | B20: 2749 | C20: 2748 | D20: 2748 | E20: 90257658 | F20: 90257658 | G20: 890501549 | H20: MPIO DE SALAZAR DE LAS PALMAS | I20: =VLOOKUP(C20,'mayo-26'!B:H,7,0) -> CALLE 2 CARRERA 6 ESQUINA | J20: 0 | K20: DF | L20: DF | M20: CÚCUTA MPO | N20: CUCUTA ZONA SUR | O20: 1001 - CICL FACT PARQUE GUAYABAL( 63) | P20: DIS. FINAL Y TRATAMIENTO | Q20: NO RESIDENCIAL - ASEO GP | R20: INDUSTRIAL | S20: AFORO PERMANENTE | T20: Ocupado | U20: 2026 | V20: 6 | W20: 1081874796 | X20: 1081893268 | Y20: 09-06-2026 | Z20: 04-07-2026 | AA20: 3698278.6 | AB20: 3698278.6 | AC20: 0 | AD20: 78660 | AE20: 0 | AF20: 0 | AG20: 0 | AH20: 0 | AI20: 0 | AJ20: 3698278.6 | AK20: 3698279.2 | AL20: 1 | AM20: 1078035.3 | AN20: 0 | AS20: =VLOOKUP(C20,'mayo-26'!B:AS,44,0) -> HACIENDA@SALAZARDELASPALMAS-NORTEDESANTANDER.GOV.CO | AT20: =VLOOKUP(C20,'mayo-26'!B:AT,45,0) -> CORREO ELECTRONICO CERTIFICADO 472
A21: 235eb13c11bfae5cc864908b4cc63d0454ae6fcb88e5730d02bc3f78058c0107e8f05a4ad17d2e28b68340b98042d407 | B21: 2753 | C21: 2752 | D21: 2752 | E21: 90257711 | F21: 90257711 | G21: 807002043 | H21: EMZULIA E.S.P | I21: =VLOOKUP(C21,'mayo-26'!B:H,7,0) -> CLL 7 NO 2-03 BARRIO CENTRO MUNICIPIO EL ZULIA | J21: 0 | K21: DF | L21: DF | M21: CÚCUTA MPO | N21: CUCUTA ZONA SUR | O21: 1001 - CICL FACT PARQUE GUAYABAL( 63) | P21: DIS. FINAL Y TRATAMIENTO | Q21: NO RESIDENCIAL - ASEO GP | R21: INDUSTRIAL | S21: AFORO PERMANENTE | T21: Ocupado | U21: 2026 | V21: 6 | W21: 1081874798 | X21: 1081893270 | Y21: 09-06-2026 | Z21: 04-07-2026 | AA21: 23217911 | AB21: 23217911 | AC21: 0 | AD21: 493830 | AE21: 0 | AF21: 0 | AG21: 0 | AH21: 0 | AI21: 0 | AJ21: 23217911 | AK21: 23217912 | AL21: 1 | AM21: 6767940.2 | AN21: 0 | AS21: =VLOOKUP(C21,'mayo-26'!B:AS,44,0) -> emzulia.esp@gmail.com | AT21: =VLOOKUP(C21,'mayo-26'!B:AT,45,0) -> CORREO ELECTRONICO CERTIFICADO 472
A22: b015e76d8cd7b4283b2939c11b585a598e48edb0c3ed9d90d84a944d35fd2d244a5300a176f5e84c922414850d6c5f68 | B22: 2757 | C22: 2756 | D22: 2756 | E22: 90257826 | F22: 90257826 | G22: 890505662 | H22: MUNICIPIO DE BOCHALEMA | I22: =VLOOKUP(C22,'mayo-26'!B:H,7,0) -> CALLE 3 NO 3 - 08 | J22: 0 | K22: DF | L22: DF | M22: CÚCUTA MPO | N22: CUCUTA ZONA SUR | O22: 1001 - CICL FACT PARQUE GUAYABAL( 63) | P22: DIS. FINAL Y TRATAMIENTO | Q22: NO RESIDENCIAL - ASEO GP | R22: OFICIAL | S22: AFORO PERMANENTE | T22: Ocupado | U22: 2026 | V22: 6 | W22: 1081874803 | X22: 1081893275 | Y22: 09-06-2026 | Z22: 04-07-2026 | AA22: 4604747 | AB22: 4604747 | AC22: 0 | AD22: 97940 | AE22: 0 | AF22: 0 | AG22: 0 | AH22: 0 | AI22: 0 | AJ22: 4604747 | AK22: 4604747 | AL22: 0 | AM22: 1342267.7 | AN22: 0 | AS22: =VLOOKUP(C22,'mayo-26'!B:AS,44,0) -> UNISEPUBLICOS@BOCHALEMA-NORTEDESANTANDER.GOV.CO | AT22: =VLOOKUP(C22,'mayo-26'!B:AT,45,0) -> CORREO ELECTRONICO CERTIFICADO 472
A23: 7e3cc58fe6b22654849ce56d89fa529dd13986e13f68b2bf91497a458ead91d23947a6da9321dffcede2f195fb007c1b | B23: 433 | C23: 432 | D23: 432 | E23: 90253757 | F23: 90253757 | G23: 901347799 | H23: CURTIEMBRES CUCUTA SAS NIT.901.347.799-4 | I23: =VLOOKUP(C23,'mayo-26'!B:H,7,0) -> KM 6 #49-40 VIA SAUFASTINO EL SERRITO | J23: SIN DETERMINAR | K23: DF | L23: DF | M23: CÚCUTA MPO | N23: CUCUTA ZONA SUR | O23: 1001 - CICL FACT PARQUE GUAYABAL( 63) | P23: DIS. FINAL Y TRATAMIENTO | Q23: NO RESIDENCIAL - ASEO GP | R23: INDUSTRIAL | S23: AFORO PERMANENTE | T23: Ocupado | U23: 2026 | V23: 6 | W23: 1081874774 | X23: 1081893246 | Y23: 09-06-2026 | Z23: 04-07-2026 | AA23: 614063.39 | AB23: 614063.39 | AC23: 0 | AD23: 14470 | AE23: 0 | AF23: 0 | AG23: 0 | AH23: 0 | AI23: 0 | AJ23: 614063.39 | AK23: 614063.39 | AL23: 0 | AM23: 132053.22 | AN23: 0 | AS23: =VLOOKUP(C23,'mayo-26'!B:AS,44,0) -> CURTIEMBRESCUCUTA@GMAIL.COM | AT23: =VLOOKUP(C23,'mayo-26'!B:AT,45,0) -> CORREO ELECTRONICO CERTIFICADO 472
A24: 154e3276a2ee5be1e3c79d217014c51aa63cda4541f438f01d82a53c92d5c569623190fdf4e7d4b601852399c3ae8a75 | B24: 505 | C24: 504 | D24: 504 | E24: 90268059 | F24: 90268059 | G24: 60366490 | H24: NATALIA ANDREA ROJAS | I24: =VLOOKUP(C24,'mayo-26'!B:H,7,0) -> CLL 21 0E- 20 CAOBOS | J24: BARRIO BLANCO | K24: DF | L24: DF | M24: CÚCUTA MPO | N24: CUCUTA DIRECTA | O24: 1001 - CICL FACT PARQUE GUAYABAL( 63) | P24: DIS. FINAL Y TRATAMIENTO | Q24: NO RESIDENCIAL - ASEO GP | R24: INDUSTRIAL | S24: AFORO PERMANENTE | T24: Ocupado | U24: 2026 | V24: 6 | W24: 1081874775 | X24: 1081893247 | Y24: 09-06-2026 | Z24: 04-07-2026 | AA24: 891328.21 | AB24: 891328.21 | AC24: 0 | AD24: 20240 | AE24: 32403.33 | AF24: 0 | AG24: 0 | AH24: 0 | AI24: 0 | AJ24: 891328.21 | AK24: 2500616.3 | AL24: 3 | AM24: 184710.24 | AN24: 0 | AS24: =VLOOKUP(C24,'mayo-26'!B:AS,44,0) -> NAROHE10@HOTMAIL.COM | AT24: =VLOOKUP(C24,'mayo-26'!B:AT,45,0) -> CORREO ELECTRONICO CERTIFICADO 472
A25: 96c389aa258a0a1e4cd305479a4718bec257a95d6e29eed1e69122ea8db40bfb3841511a7e4b84e15a2e854ac9594eef | B25: 605804 | C25: 502000 | D25: 557773 | G25: 901951147 | H25: ASEOCATATUMBO S.A.S. ESP | I25: =VLOOKUP(C25,'mayo-26'!B:H,7,0) -> #N/A | J25: #N/A | K25: DF | L25: DF | M25: CÚCUTA MPO | N25: CUCUTA DIRECTA | O25: 1001 - CICL FACT PARQUE GUAYABAL( 63) | P25: ASEO INTEGRAL | Q25: NO RESIDENCIAL - ASEO GP | R25: COMERCIAL | S25: AFORO PERMANENTE | T25: Ocupado | U25: 2026 | V25: 6 | W25: 1081884177 | X25: 1081902670 | Y25: 09-06-2026 | Z25: 04-07-2026 | AA25: 4405399 | AB25: 4405399 | AC25: 0 | AD25: 0 | AE25: 0 | AF25: 0 | AG25: 0 | AH25: 0 | AI25: 0 | AJ25: 4405387.9 | AK25: 4405387.9 | AL25: 0 | AM25: 1284158 | AN25: 0 | AQ25: 11.13 | AS25: =VLOOKUP(C25,'mayo-26'!B:AS,44,0) -> #N/A | AT25: =VLOOKUP(C25,'mayo-26'!B:AT,45,0) -> #N/A
A26: c65c098c83979c0954e821249927b3f03859ea922b24b959ecd3a85e56bd4096fd7c8ca057f8ad912014d3fc855a5bd8 | B26: 285191 | C26: 217711 | D26: 217711 | E26: 40520 | F26: 40520 | G26: 900276962 | H26: D1 S A S | I26: =VLOOKUP(C26,'mayo-26'!B:H,7,0) -> KDX 73-2 1116 | J26: ATALAYA | K26: =VLOOKUP(C26,'mayo-26'!B:J,9,0) -> NO | L26: =VLOOKUP(C26,'mayo-26'!B:K,10,0) -> D1 | M26: CÚCUTA MPO | N26: CUCUTA DIRECTA | O26: 1002 - CICL FACT DIRECTA CUCUTA NORTE | P26: ASEO INTEGRAL | Q26: NO RESIDENCIAL - ASEO PP | R26: COMERCIAL RANGO 3 | S26: NO AFORADO | T26: Ocupado | U26: 2026 | V26: 6 | W26: 1081875085 | X26: 1081893557 | Y26: 46182 | Z26: 46207 | AA26: 113128.5 | AB26: 113128.5 | AC26: 37709.5 | AD26: 0 | AE26: 0 | AF26: 0 | AG26: 0 | AH26: 0 | AI26: 0 | AJ26: 113128.5 | AK26: 113128.5 | AL26: 0 | AM26: 376.2 | AN26: 0 | AS26: =VLOOKUP(C26,'mayo-26'!B:AS,44,0) -> ALBA.CELIS@D1.COM.CO;CARMEN.DAVILA@D1.COM.CO | AT26: =VLOOKUP(C26,'mayo-26'!B:AT,45,0) -> CORREO ELECTRONICO CERTIFICADO 472
A27: f49ba4dc8e59c729460cb7b7e099ba9f1abbbc0549519975e81657efd0635c24bff686c0875762014a2ffaa0e6df49f7 | B27: 297 | C27: 223223 | D27: 223223 | E27: 46258 | F27: 46258 | G27: 807004352-3 | H27: EMPRESA SOCIAL DEL ESTADO E.S.E IMSALUD | I27: =VLOOKUP(C27,'mayo-26'!B:H,7,0) -> AVE 4 17-89 - 0239431 | J27: ANTONIA SANTOS | K27: =VLOOKUP(C27,'mayo-26'!B:J,9,0) -> NO | L27: =VLOOKUP(C27,'mayo-26'!B:K,10,0) -> IMSALUD | M27: CÚCUTA MPO | N27: CUCUTA ZONA NORTE | O27: 1002 - CICL FACT DIRECTA CUCUTA NORTE | P27: ASEO INTEGRAL | Q27: NO RESIDENCIAL - ASEO PP | R27: OFICIAL RANGO 2 | S27: NO AFORADO | T27: Ocupado | U27: 2026 | V27: 6 | W27: 1081875089 | X27: 1081893561 | Y27: 46182 | Z27: 46207 | AA27: 62832 | AB27: 62832 | AC27: 0 | AD27: 0 | AE27: 0 | AF27: 0 | AG27: 0 | AH27: 0 | AI27: 0 | AJ27: 62832 | AK27: 62832 | AL27: 0 | AM27: 250.8 | AN27: 0 | AS27: =VLOOKUP(C27,'mayo-26'!B:AS,44,0) -> SUBFINANCIERA@IMSALUD.GOV.CO | AT27: =VLOOKUP(C27,'mayo-26'!B:AT,45,0) -> CORREO ELECTRONICO CERTIFICADO 472
A28: d2c80bf90fd2913c04fe311d779982fc801f62df2fba50f7698345193b304f7454850768fd0a8ddfe0747c380b1f7547 | B28: 699 | C28: 225199 | D28: 225199 | E28: 48272 | F28: 48272 | G28: 900480569 | H28: JERONIMO MARTINS COLOMBIA SAS | I28: =VLOOKUP(C28,'mayo-26'!B:H,7,0) -> CLL 12 4-52 CENTRO | J28: NIÑA CECI | K28: =VLOOKUP(C28,'mayo-26'!B:J,9,0) -> NO | L28: =VLOOKUP(C28,'mayo-26'!B:K,10,0) -> ARA CUCUTA | M28: CÚCUTA MPO | N28: CUCUTA ZONA NORTE | O28: 1002 - CICL FACT DIRECTA CUCUTA NORTE | P28: ASEO INTEGRAL | Q28: NO RESIDENCIAL - ASEO GP | R28: COMERCIAL | S28: AFORO ORDINARIO-EXTRAORDINARIO | T28: Ocupado | U28: 2026 | V28: 6 | W28: 1081875094 | X28: 1081893566 | Y28: 46182 | Z28: 46207 | AA28: 679277.47 | AB28: 679277.47 | AC28: 226425.83 | AD28: 2188 | AE28: 0 | AF28: 0 | AG28: 0 | AH28: 0 | AI28: 0 | AJ28: 679277.47 | AK28: 1359480.2 | AL28: 1 | AM28: 376.2 | AN28: 0 | AS28: =VLOOKUP(C28,'mayo-26'!B:AS,44,0) -> COORDINADOR.OPERACIONES.R11@JERONIMO-MARTINS.COM | AT28: =VLOOKUP(C28,'mayo-26'!B:AT,45,0) -> CORREO ELECTRONICO CERTIFICADO 472
A29: f794264a9dca82c39a72c392925416389fee7f8d79c375c8b7261ea454e9a351a18d865e387c8958e072886219fae897 | B29: 141 | C29: 237851 | D29: 237851 | E29: 307920 | F29: 307920 | G29: 890500514 | H29: CENTRALES ELECTRICAS DEL NORTE DE SANTANDER S.A. EMPRESA DE SERVICIOS PUBLICOS | I29: =VLOOKUP(C29,'mayo-26'!B:H,7,0) -> AV 2 CALLE 39 LIBERTAD | J29: SEVILLA | K29: =VLOOKUP(C29,'mayo-26'!B:J,9,0) -> NO | L29: =VLOOKUP(C29,'mayo-26'!B:K,10,0) -> CENS | M29: CÚCUTA MPO | N29: CUCUTA ZONA NORTE | O29: 1002 - CICL FACT DIRECTA CUCUTA NORTE | P29: ASEO INTEGRAL | Q29: NO RESIDENCIAL - ASEO GP | R29: COMERCIAL | S29: AFORO PERMANENTE | T29: Ocupado | U29: 2026 | V29: 6 | W29: 1081875098 | X29: 1081893570 | Y29: 46182 | Z29: 46207 | AA29: 728415.9 | AB29: 728415.9 | AC29: 242805.31 | AD29: 2360.63 | AE29: 0 | AF29: 0 | AG29: 0 | AH29: 0 | AI29: 0 | AJ29: 728415.9 | AK29: 728415.9 | AL29: 0 | AM29: 376.2 | AN29: 0 | AS29: =VLOOKUP(C29,'mayo-26'!B:AS,44,0) -> FACTURAELECTRONICACENS@GRUPO-EPM.COM | AT29: =VLOOKUP(C29,'mayo-26'!B:AT,45,0) -> CORREO ELECTRONICO CERTIFICADO 472
A30: abe476565549d3b780b314abf5f43e7a813492f4d2115327e5fab8ceae29acfd08cb332c3db99ad29933a01752545e77 | B30: 455370 | C30: 267583 | D30: 267583 | E30: 661467 | F30: 661467 | G30: 890501434- 2 | H30: MUNICIPIO DE SAN JOSE DE CUCUTA - SEDE TONCHALA | I30: =VLOOKUP(C30,'mayo-26'!B:H,7,0) -> CALLE 10 NO 0E-16 EDF CENTRO EMPRESARIAL BLOQUE B HOTEL TONCHALA | J30: LA PRIMAVERA | K30: =VLOOKUP(C30,'mayo-26'!B:J,9,0) -> NO | L30: =VLOOKUP(C30,'mayo-26'!B:K,10,0) -> COLEGIOS ZONA NORTE | M30: CÚCUTA MPO | N30: CUCUTA ZONA NORTE | O30: 1002 - CICL FACT DIRECTA CUCUTA NORTE | P30: ASEO INTEGRAL | Q30: NO RESIDENCIAL - ASEO PP | R30: OFICIAL RANGO 3 | S30: NO AFORADO | T30: Ocupado | U30: 2026 | V30: 6 | W30: 1081875102 | X30: 1081893574 | Y30: 46182 | Z30: 46207 | AA30: 75419 | AB30: 75419 | AC30: 0 | AD30: 0 | AE30: 0 | AF30: 0 | AG30: 0 | AH30: 0 | AI30: 0 | AJ30: 75419 | AK30: 82922 | AL30: 1 | AM30: 250.8 | AN30: 0 | AS30: =VLOOKUP(C30,'mayo-26'!B:AS,44,0) -> AREAFINANCIERA@SEMCUCUTA.GOV.CO | AT30: =VLOOKUP(C30,'mayo-26'!B:AT,45,0) -> CARTERA
A31: cf8048c7c550050a32f66cb59fad4752d8557c36abafef23c528d334d048679adada563ded0b77b5f6448cab7d196055 | B31: 269532 | C31: 269531 | D31: 269531 | E31: 676425 | F31: 676425 | G31: 900117563-3 | H31: COMPAÑIA MINERA CERRO TASAJERO SA- | I31: =VLOOKUP(C31,'mayo-26'!B:H,7,0) -> CERRO TASAJERO- VIA SAN FAUSTINO | J31: VDA PASO DE LOS RIOS | K31: =VLOOKUP(C31,'mayo-26'!B:J,9,0) -> NO | L31: =VLOOKUP(C31,'mayo-26'!B:K,10,0) -> NO | M31: CÚCUTA MPO | N31: CUCUTA DIRECTA | O31: 1002 - CICL FACT DIRECTA CUCUTA NORTE | P31: ASEO INTEGRAL | Q31: NO RESIDENCIAL - ASEO PP | R31: COMERCIAL RANGO 3 | S31: NO AFORADO | T31: Ocupado | U31: 2026 | V31: 6 | W31: 1081875106 | X31: 1081893578 | Y31: 46182 | Z31: 46207 | AA31: 113128.5 | AB31: 113128.5 | AC31: 37709.5 | AD31: 0 | AE31: 0 | AF31: 0 | AG31: 0 | AH31: 0 | AI31: 0 | AJ31: 113128.5 | AK31: 113128.5 | AL31: 0 | AM31: 376.2 | AN31: 0 | AS31: =VLOOKUP(C31,'mayo-26'!B:AS,44,0) -> FACTURACIONEMNFC@HOTMAIL.COM | AT31: =VLOOKUP(C31,'mayo-26'!B:AT,45,0) -> CORREO ELECTRONICO CERTIFICADO 472
A32: c012604be3ccb4319ac41d67bce25ab8d36a5996952472285331425bd3bbf6850510b6d3c07d7cd0820739e6a6c0f1d1 | B32: 699 | C32: 274211 | D32: 274211 | E32: 1731 | F32: 1731 | G32: 900480569 | H32: JERONIMO MARTINS COLOMBIA SAS | I32: =VLOOKUP(C32,'mayo-26'!B:H,7,0) -> CLL 12 4-52 CENTRO | J32: BELEN | K32: =VLOOKUP(C32,'mayo-26'!B:J,9,0) -> NO | L32: =VLOOKUP(C32,'mayo-26'!B:K,10,0) -> ARA CUCUTA | M32: CÚCUTA MPO | N32: CUCUTA ZONA NORTE | O32: 1002 - CICL FACT DIRECTA CUCUTA NORTE | P32: ASEO INTEGRAL | Q32: NO RESIDENCIAL - ASEO GP | R32: COMERCIAL | S32: AFORO ORDINARIO-EXTRAORDINARIO | T32: Ocupado | U32: 2026 | V32: 6 | W32: 1081875109 | X32: 1081893581 | Y32: 46182 | Z32: 46207 | AA32: 484707.7 | AB32: 484707.7 | AC32: 158774.97 | AD32: 1475 | AE32: 8382.82 | AF32: 0 | AG32: 0 | AH32: 0 | AI32: 0 | AJ32: 484707.7 | AK32: 961907.56 | AL32: 1 | AM32: 376.2 | AN32: 0 | AS32: =VLOOKUP(C32,'mayo-26'!B:AS,44,0) -> COORDINADOR.OPERACIONES.R11@JERONIMO-MARTINS.COM | AT32: =VLOOKUP(C32,'mayo-26'!B:AT,45,0) -> CORREO ELECTRONICO CERTIFICADO 472
A33: 2b00456968c64348e6a57be6ec661ecbd1f1a392ea7702d524389261c0059d80904f9087d668aeabfbf515175532e76a | B33: 699 | C33: 276691 | D33: 276691 | E33: 18151 | F33: 18151 | G33: 900480569 | H33: JERONIMO MARTINS COLOMBIA SAS | I33: =VLOOKUP(C33,'mayo-26'!B:H,7,0) -> CLL 12 4-52 CENTRO | J33: SAN MIGUEL | K33: =VLOOKUP(C33,'mayo-26'!B:J,9,0) -> NO | L33: =VLOOKUP(C33,'mayo-26'!B:K,10,0) -> ARA CUCUTA | M33: CÚCUTA MPO | N33: CUCUTA ZONA NORTE | O33: 1002 - CICL FACT DIRECTA CUCUTA NORTE | P33: ASEO INTEGRAL | Q33: NO RESIDENCIAL - ASEO GP | R33: COMERCIAL | S33: AFORO ORDINARIO-EXTRAORDINARIO | T33: Ocupado | U33: 2026 | V33: 6 | W33: 1081875115 | X33: 1081893587 | Y33: 46182 | Z33: 46207 | AA33: 359246.29 | AB33: 359246.29 | AC33: 119209.17 | AD33: 1058 | AE33: 1618.8 | AF33: 0 | AG33: 0 | AH33: 0 | AI33: 0 | AJ33: 359246.29 | AK33: 717719.36 | AL33: 1 | AM33: 376.2 | AN33: 0 | AS33: =VLOOKUP(C33,'mayo-26'!B:AS,44,0) -> COORDINADOR.OPERACIONES.R11@JERONIMO-MARTINS.COM | AT33: =VLOOKUP(C33,'mayo-26'!B:AT,45,0) -> CORREO ELECTRONICO CERTIFICADO 472
A34: e0b72d379a22f8a196ac2e59fa43a6c5c4b848a7460ae8b4c67ea0e582e711bc9d72be7101f7a7a875c14e84d75169ed | B34: 280920 | C34: 279767 | D34: 279767 | E34: 24737 | F34: 24737 | G34: 900576569 | H34: SUPERMERCADO BETEL PLUSS | I34: =VLOOKUP(C34,'mayo-26'!B:H,7,0) -> AVE 12 5AN-84 1142 | J34: CALLEJON | K34: =VLOOKUP(C34,'mayo-26'!B:J,9,0) -> NO | L34: =VLOOKUP(C34,'mayo-26'!B:K,10,0) -> BETEL | M34: CÚCUTA MPO | N34: CUCUTA DIRECTA | O34: 1002 - CICL FACT DIRECTA CUCUTA NORTE | P34: ASEO INTEGRAL | Q34: NO RESIDENCIAL - ASEO PP | R34: COMERCIAL RANGO 3 | S34: NO AFORADO | T34: Desocupado | U34: 2026 | V34: 6 | W34: 1081875120 | X34: 1081893592 | Y34: 46182 | Z34: 46207 | AA34: 91936.97 | AB34: 91936.97 | AC34: 18616 | AD34: 0 | AE34: 36088.97 | AF34: 0 | AG34: 0 | AH34: 0 | AI34: 0 | AJ34: 91936.97 | AK34: 2133376.2 | AL34: 15 | AM34: 376.2 | AN34: 0 | AS34: =VLOOKUP(C34,'mayo-26'!B:AS,44,0) -> COORDTESORERIASUPERBETEL@GMAIL.COM | AT34: =VLOOKUP(C34,'mayo-26'!B:AT,45,0) -> CORREO ELECTRONICO CERTIFICADO 472
A35: ceda3cbef11f230c48e332f91b52b748e70eb68dcd7ad81ece42de7168b9da3e9efad0ffa9049a0497393114aeece2cd | B35: 280920 | C35: 280919 | D35: 280919 | E35: 29336 | F35: 29336 | G35: 900576569 | H35: SUPERMERCADO BETEL PLUSS | I35: =VLOOKUP(C35,'mayo-26'!B:H,7,0) -> AVE 12 5AN-84 1142 | J35: CHAPINERO | K35: =VLOOKUP(C35,'mayo-26'!B:J,9,0) -> NO | L35: =VLOOKUP(C35,'mayo-26'!B:K,10,0) -> BETEL | M35: CÚCUTA MPO | N35: CUCUTA DIRECTA | O35: 1002 - CICL FACT DIRECTA CUCUTA NORTE | P35: ASEO INTEGRAL | Q35: NO RESIDENCIAL - ASEO GP | R35: COMERCIAL | S35: AFORO ORDINARIO-EXTRAORDINARIO | T35: Ocupado | U35: 2026 | V35: 6 | W35: 1081875126 | X35: 1081893598 | Y35: 46182 | Z35: 46207 | AA35: 1647727.4 | AB35: 1647727.4 | AC35: 543284.27 | AD35: 5527.5 | AE35: 17874.57 | AF35: 0 | AG35: 0 | AH35: 0 | AI35: 0 | AJ35: 1647727.4 | AK35: 4957988.2 | AL35: 3 | AM35: 376.2 | AN35: 0 | AS35: =VLOOKUP(C35,'mayo-26'!B:AS,44,0) -> COORDTESORERIASUPERBETEL@GMAIL.COM | AT35: =VLOOKUP(C35,'mayo-26'!B:AT,45,0) -> CORREO ELECTRONICO CERTIFICADO 472
A36: 98372cea1076bb4def88d8f3920166b95ce4d9ca0b22090e006af46585b8fcd6420f0441d6486ec8ad919e2236728de3 | B36: 297 | C36: 292435 | D36: 292435 | E36: 101989 | F36: 101989 | G36: 807004352-3 | H36: EMPRESA SOCIAL DEL ESTADO E.S.E IMSALUD | I36: =VLOOKUP(C36,'mayo-26'!B:H,7,0) -> AVE 4 17-89 - 0239431 | J36: CUNDINAMARCA | K36: =VLOOKUP(C36,'mayo-26'!B:J,9,0) -> NO | L36: =VLOOKUP(C36,'mayo-26'!B:K,10,0) -> IMSALUD | M36: CÚCUTA MPO | N36: CUCUTA ZONA NORTE | O36: 1002 - CICL FACT DIRECTA CUCUTA NORTE | P36: ASEO INTEGRAL | Q36: NO RESIDENCIAL - ASEO PP | R36: OFICIAL RANGO 3 | S36: NO AFORADO | T36: Ocupado | U36: 2026 | V36: 6 | W36: 1081875130 | X36: 1081893602 | Y36: 46182 | Z36: 46207 | AA36: 75419 | AB36: 75419 | AC36: 0 | AD36: 0 | AE36: 0 | AF36: 0 | AG36: 0 | AH36: 0 | AI36: 0 | AJ36: 75419 | AK36: 75419 | AL36: 0 | AM36: 250.8 | AN36: 0 | AS36: =VLOOKUP(C36,'mayo-26'!B:AS,44,0) -> SUBFINANCIERA@IMSALUD.GOV.CO | AT36: =VLOOKUP(C36,'mayo-26'!B:AT,45,0) -> CORREO ELECTRONICO CERTIFICADO 472
A37: 005b0abbbfa859095f2091976748af27fd53c7f18de1e949308e6e3c9689bfdd91cd4f365d5428df575605a0575b2cc7 | B37: 297 | C37: 292975 | D37: 292975 | E37: 155089 | F37: 155089 | G37: 807004352-3 | H37: EMPRESA SOCIAL DEL ESTADO E.S.E IMSALUD | I37: =VLOOKUP(C37,'mayo-26'!B:H,7,0) -> AVE 4 17-89 - 0239431 | J37: CHAPINERO | K37: =VLOOKUP(C37,'mayo-26'!B:J,9,0) -> NO | L37: =VLOOKUP(C37,'mayo-26'!B:K,10,0) -> IMSALUD | M37: CÚCUTA MPO | N37: CUCUTA ZONA NORTE | O37: 1002 - CICL FACT DIRECTA CUCUTA NORTE | P37: ASEO INTEGRAL | Q37: NO RESIDENCIAL - ASEO PP | R37: OFICIAL RANGO 2 | S37: NO AFORADO | T37: Ocupado | U37: 2026 | V37: 6 | W37: 1081875134 | X37: 1081893606 | Y37: 46182 | Z37: 46207 | AA37: 62832 | AB37: 62832 | AC37: 0 | AD37: 0 | AE37: 0 | AF37: 0 | AG37: 0 | AH37: 0 | AI37: 0 | AJ37: 62832 | AK37: 62832 | AL37: 0 | AM37: 250.8 | AN37: 0 | AS37: =VLOOKUP(C37,'mayo-26'!B:AS,44,0) -> SUBFINANCIERA@IMSALUD.GOV.CO | AT37: =VLOOKUP(C37,'mayo-26'!B:AT,45,0) -> CORREO ELECTRONICO CERTIFICADO 472
A38: 913562c1cf026633e5014bfb02234cc07196647f821cda9ce4037c8a6dcf836e6f18752fdd124c4602e366f256f04e60 | B38: 297 | C38: 295095 | D38: 295095 | E38: 186399 | F38: 186399 | G38: 807004352-3 | H38: EMPRESA SOCIAL DEL ESTADO E.S.E IMSALUD | I38: =VLOOKUP(C38,'mayo-26'!B:H,7,0) -> AVE 4 17-89 - 0239431 | J38: SEVILLA | K38: =VLOOKUP(C38,'mayo-26'!B:J,9,0) -> NO | L38: =VLOOKUP(C38,'mayo-26'!B:K,10,0) -> IMSALUD | M38: CÚCUTA MPO | N38: CUCUTA ZONA NORTE | O38: 1002 - CICL FACT DIRECTA CUCUTA NORTE | P38: ASEO INTEGRAL | Q38: NO RESIDENCIAL - ASEO GP | R38: OFICIAL | S38: AFORO ORDINARIO-EXTRAORDINARIO | T38: Ocupado | U38: 2026 | V38: 6 | W38: 1081875136 | X38: 1081893608 | Y38: 46182 | Z38: 46207 | AA38: 104065.4 | AB38: 104065.4 | AC38: 0 | AD38: 350 | AE38: 0 | AF38: 0 | AG38: 0 | AH38: 0 | AI38: 0 | AJ38: 104065.4 | AK38: 104065.4 | AL38: 0 | AM38: 250.8 | AN38: 0 | AS38: =VLOOKUP(C38,'mayo-26'!B:AS,44,0) -> SUBFINANCIERA@IMSALUD.GOV.CO | AT38: =VLOOKUP(C38,'mayo-26'!B:AT,45,0) -> CORREO ELECTRONICO CERTIFICADO 472
A39: 6aeb5def2380d1e27808a9c5db826fbac00dbf50a244dd32a35ae4754197f4d7b23486485797a237ab1a88f7c1f3d80a | B39: 299352 | C39: 299351 | D39: 299351 | E39: 206188 | F39: 206188 | G39: 60353386 | H39: EMBUTIDOS CARNEVALI/CARNES FRIAS DEL ORIENTE | I39: =VLOOKUP(C39,'mayo-26'!B:H,7,0) -> AVE 6 17N-71 1219 | J39: ZONA INDUSTRIAL | K39: =VLOOKUP(C39,'mayo-26'!B:J,9,0) -> NO | L39: =VLOOKUP(C39,'mayo-26'!B:K,10,0) -> NO | M39: CÚCUTA MPO | N39: CUCUTA DIRECTA | O39: 1002 - CICL FACT DIRECTA CUCUTA NORTE | P39: ASEO INTEGRAL | Q39: NO RESIDENCIAL - ASEO GP | R39: INDUSTRIAL | S39: AFORO PERMANENTE | T39: Ocupado | U39: 2026 | V39: 6 | W39: 1081875139 | X39: 1081893611 | Y39: 46182 | Z39: 46207 | AA39: 1100472.2 | AB39: 1100472.2 | AC39: 253955.11 | AD39: 4262.5 | AE39: 0 | AF39: 0 | AG39: 0 | AH39: 0 | AI39: 0 | AJ39: 1100472.2 | AK39: 2026413.8 | AL39: 1 | AM39: 326.04 | AN39: 0 | AS39: =VLOOKUP(C39,'mayo-26'!B:AS,44,0) -> ADM.CARNEVALI@GMAIL.COM | AT39: =VLOOKUP(C39,'mayo-26'!B:AT,45,0) -> CORREO ELECTRONICO CERTIFICADO 472
A40: 0f39ab1a1354cc528180c73d946ab1874adf6d9d94c3f0250a385517c91ad4e4f45e509d8d6d9d61c6548339ed99834c | B40: 297 | C40: 307735 | D40: 307735 | E40: 307162 | F40: 307162 | G40: 807004352-3 | H40: EMPRESA SOCIAL DEL ESTADO E.S.E IMSALUD | I40: =VLOOKUP(C40,'mayo-26'!B:H,7,0) -> AVE 4 17-89 - 0239431 | J40: BELEN | K40: =VLOOKUP(C40,'mayo-26'!B:J,9,0) -> NO | L40: =VLOOKUP(C40,'mayo-26'!B:K,10,0) -> IMSALUD | M40: CÚCUTA MPO | N40: CUCUTA ZONA NORTE | O40: 1002 - CICL FACT DIRECTA CUCUTA NORTE | P40: ASEO INTEGRAL | Q40: NO RESIDENCIAL - ASEO GP | R40: OFICIAL | S40: AFORO ORDINARIO-EXTRAORDINARIO | T40: Ocupado | U40: 2026 | V40: 6 | W40: 1081875143 | X40: 1081893615 | Y40: 46182 | Z40: 46207 | AA40: 105963.04 | AB40: 105963.04 | AC40: 0 | AD40: 360 | AE40: 0 | AF40: 0 | AG40: 0 | AH40: 0 | AI40: 0 | AJ40: 105963.04 | AK40: 105963.04 | AL40: 0 | AM40: 250.8 | AN40: 0 | AS40: =VLOOKUP(C40,'mayo-26'!B:AS,44,0) -> SUBFINANCIERA@IMSALUD.GOV.CO | AT40: =VLOOKUP(C40,'mayo-26'!B:AT,45,0) -> CORREO ELECTRONICO CERTIFICADO 472
...

Sheet mayo-26
A1: Cliente | B1: Cuenta | C1: Producto | D1: NIC | E1: NIS | F1: Identificación | G1: Nombres | H1: direccion | I1: barrio | J1: Planilla | K1: Grupo empresarial | L1: Nombre Municipio | M1: Cod. Localidad | N1: Ciclo de consumo | O1: Plan de facturación | P1: Categoría | Q1: Subcategoría | R1: Método de análisis | S1: Estado | T1: Año | U1: Mes(es) | V1: Factura | W1: Cuenta de cobro | X1: Generada el | Y1: Vence el | Z1: Total Cuenta | AA1: Monto facturado | AB1: Subsidio y/o Contribuciones | AC1: Consumo | AD1: VALOR INGRESOS INTERESES | AE1: Valor De Financiaciones | AF1: Cuota | AG1: Interes Financiacion | AH1: TOTAL IMPUESTO | AI1: Saldo pendiente | AJ1: Deuda Total | AK1: Cuentas Vencidas | AL1: Valor_Otros | AM1: Valor Nota | AN1: Valor Movimiento SA | AO1: Valor de pago | AP1: Valor Movimiento AS | AQ1: Fecha de Pago | AR1: Saldo a favor | AS1: CORREO | AT1: MEDIO DE ENVIO | AU1: responsable | AV1: FECHA
A2: 2743 | B2: 2742 | C2: 2742 | D2: 90255897 | E2: 90255897 | F2: 890506116-8 | G2: ALCALDIA PAMPLONITA | H2: #N/A | I2: PAMPLONITA | J2: DF | K2: DF | L2: CÚCUTA MPO | M2: CUCUTA ZONA SUR | N2: 1001 - CICL FACT PARQUE GUAYABAL( 63) | O2: DIS. FINAL Y TRATAMIENTO | P2: NO RESIDENCIAL - ASEO GP | Q2: OFICIAL | R2: AFORO PERMANENTE | S2: Ocupado | T2: 2026 | U2: 5 | V2: 1081522141 | W2: 1081540211 | X2: 08-05-2026 | Y2: 03-06-2026 | Z2: 173662.47 | AA2: 173662.47 | AB2: 0 | AC2: 3690 | AD2: 0 | AE2: 0 | AF2: 0 | AG2: 0 | AH2: 0 | AI2: 173662.47 | AJ2: 173662.47 | AK2: 0 | AL2: 50571.45 | AM2: 0 | AR2: 0 | AS2: serviciospublicos@pamplonita-nortedesantander.gov.co | AT2: CORREO ELECTRONICO CERTIFICADO 472 | AU2: ANGEL | AV2: 46171
A3: 2747 | B3: 2746 | C3: 2746 | D3: 90256627 | E3: 90256627 | F3: 800099237 | G3: EMPODURANIA | H3: AVENIDA 2 NO. 8-57 | I3: 0 | J3: NO | K3: DF | L3: CÚCUTA MPO | M3: CUCUTA ZONA SUR | N3: 1001 - CICL FACT PARQUE GUAYABAL( 63) | O3: DIS. FINAL Y TRATAMIENTO | P3: NO RESIDENCIAL - ASEO GP | Q3: INDUSTRIAL | R3: AFORO PERMANENTE | S3: Ocupado | T3: 2026 | U3: 5 | V3: 1081522145 | W3: 1081540215 | X3: 08-05-2026 | Y3: 03-06-2026 | Z3: 2077831.4 | AA3: 2077831.4 | AB3: 0 | AC3: 44150 | AD3: 0 | AE3: 0 | AF3: 0 | AG3: 0 | AH3: 0 | AI3: 2077831.4 | AJ3: 2077831.4 | AK3: 0 | AL3: 605075.75 | AM3: 0 | AR3: 0 | AS3: CONTACTENOS@DURANIA-NORTEDESANTANDER.GOV.CO | AT3: CORREO ELECTRONICO CERTIFICADO 472 | AU3: ANGEL | AV3: 46169
A4: 2751 | B4: 2750 | C4: 2750 | D4: 90257709 | E4: 90257709 | F4: 890501404 | G4: MUNICIPIO DE GRAMALOTE | H4: CARRERA 5 NO 7 ¿ 72 | I4: 0 | J4: NO | K4: DF | L4: CÚCUTA MPO | M4: CUCUTA ZONA SUR | N4: 1001 - CICL FACT PARQUE GUAYABAL( 63) | O4: DIS. FINAL Y TRATAMIENTO | P4: NO RESIDENCIAL - ASEO GP | Q4: OFICIAL | R4: AFORO PERMANENTE | S4: Ocupado | T4: 2026 | U4: 5 | V4: 1081522150 | W4: 1081540220 | X4: 08-05-2026 | Y4: 03-06-2026 | Z4: 2062771.3 | AA4: 2062771.3 | AB4: 0 | AC4: 43830 | AD4: 0 | AE4: 0 | AF4: 0 | AG4: 0 | AH4: 0 | AI4: 2062771.3 | AJ4: 2062771.3 | AK4: 0 | AL4: 600690.15 | AM4: 0 | AR4: 0 | AS4: TESORERIA@GRAMALOTE-NORTEDESANTANDER.GOV.CO | AT4: CORREO ELECTRONICO CERTIFICADO 472 | AU4: ANGEL | AV4: 46169
A5: 2755 | B5: 2754 | C5: 2754 | D5: 90257713 | E5: 90257713 | F5: 890502611 | G5: MUNICIPIO DE LOURDES | H5: CARRERA 4 CON CALLE 3 ¿ 36 | I5: 0 | J5: NO | K5: DF | L5: CÚCUTA MPO | M5: CUCUTA ZONA SUR | N5: 1001 - CICL FACT PARQUE GUAYABAL( 63) | O5: DIS. FINAL Y TRATAMIENTO | P5: NO RESIDENCIAL - ASEO GP | Q5: OFICIAL | R5: AFORO PERMANENTE | S5: Ocupado | T5: 2026 | U5: 5 | V5: 1081522154 | W5: 1081540224 | X5: 08-05-2026 | Y5: 03-06-2026 | Z5: 1650970 | AA5: 1650970 | AB5: 0 | AC5: 35080 | AD5: 0 | AE5: 0 | AF5: 0 | AG5: 0 | AH5: 0 | AI5: 1650970 | AJ5: 1650970 | AK5: 0 | AL5: 480771.4 | AM5: 0 | AR5: 0 | AS5: TESORERIA@LOURDES-NORTEDESANTANDER.GOV.CO | AT5: CORREO ELECTRONICO CERTIFICADO 472 | AU5: ANGEL | AV5: 46169
A6: 407715 | B6: 383058 | C6: 395995 | F6: 901196259-1 | G6: EXPLOTACIONES MINERAS DEL NORTE FC S.A.S. | H6: #N/A | I6: #N/A | J6: DF | K6: DF | L6: CÚCUTA MPO | M6: CUCUTA DIRECTA | N6: 1001 - CICL FACT PARQUE GUAYABAL( 63) | O6: DIS. FINAL Y TRATAMIENTO | P6: NO RESIDENCIAL - ASEO GP | Q6: INDUSTRIAL | R6: AFORO PERMANENTE | S6: Ocupado | T6: 2026 | U6: 5 | V6: 1081522164 | W6: 1081540234 | X6: 08-05-2026 | Y6: 03-06-2026 | Z6: 82843.8 | AA6: 82843.8 | AB6: 0 | AC6: 1950 | AD6: 0 | AE6: 0 | AF6: 0 | AG6: 0 | AH6: 0 | AI6: 82843.8 | AJ6: 82843.8 | AK6: 0 | AL6: 17795.7 | AM6: 0 | AR6: 0 | AS6: FACTURACIONEMNFC@HOTMAIL.COM | AT6: CORREO ELECTRONICO CERTIFICADO 472 | AU6: ANGEL | AV6: 46171
A7: 2744 | B7: 2743 | C7: 2743 | D7: 90256510 | E7: 90256510 | F7: 800099262 | G7: ALCALDIA MUNICIPIO DE SANTIAGO | H7: CARRERA 3 NO. 2-31 | I7: 0 | J7: NO | K7: DF | L7: CÚCUTA MPO | M7: CUCUTA ZONA SUR | N7: 1001 - CICL FACT PARQUE GUAYABAL( 63) | O7: DIS. FINAL Y TRATAMIENTO | P7: NO RESIDENCIAL - ASEO GP | Q7: OFICIAL | R7: AFORO PERMANENTE | S7: Ocupado | T7: 2026 | U7: 5 | V7: 1081522151 | W7: 1081540221 | X7: 08-05-2026 | Y7: 03-06-2026 | Z7: 1063623.8 | AA7: 1063623.8 | AB7: 0 | AC7: 22600 | AD7: 0 | AE7: 0 | AF7: 0 | AG7: 0 | AH7: 0 | AI7: 1063623.8 | AJ7: 2467983.7 | AK7: 1 | AL7: 309733 | AM7: 0 | AR7: 0 | AS7: TESORERIA@SANTIAGO-NORTEDESANTANDER.GOV.CO | AT7: CORREO ELECTRONICO CERTIFICADO 472 | AU7: ANGEL | AV7: 46169
A8: 2748 | B8: 2747 | C8: 2747 | D8: 90256652 | E8: 90256652 | F8: 890503483-2 | G8: ALCALDIA BUCARASICA | H8: CALLE 2 NO. 3-35 | I8: 0 | J8: NO | K8: DF | L8: CÚCUTA MPO | M8: CUCUTA ZONA SUR | N8: 1001 - CICL FACT PARQUE GUAYABAL( 63) | O8: DIS. FINAL Y TRATAMIENTO | P8: NO RESIDENCIAL - ASEO GP | Q8: OFICIAL | R8: AFORO PERMANENTE | S8: Ocupado | T8: 2026 | U8: 5 | V8: 1081522155 | W8: 1081540225 | X8: 08-05-2026 | Y8: 03-06-2026 | Z8: 973262.84 | AA8: 973262.84 | AB8: 0 | AC8: 20680 | AD8: 0 | AE8: 0 | AF8: 0 | AG8: 0 | AH8: 0 | AI8: 973262.84 | AJ8: 973262.84 | AK8: 0 | AL8: 283419.4 | AM8: 0 | AR8: 0 | AS8: HACIENDA@BUCARASICA-NORTEDESANTANDER.GOV.CO | AT8: CORREO ELECTRONICO CERTIFICADO 472 | AU8: ANGEL | AV8: 46170
A9: 2752 | B9: 2751 | C9: 2751 | D9: 90257710 | E9: 90257710 | F9: 890501876 | G9: MUNICIPIO DE SAN CAYETANO | H9: CARRERA 4 N 3 -61 | I9: 0 | J9: NO | K9: DF | L9: CÚCUTA MPO | M9: CUCUTA ZONA SUR | N9: 1001 - CICL FACT PARQUE GUAYABAL( 63) | O9: DIS. FINAL Y TRATAMIENTO | P9: NO RESIDENCIAL - ASEO GP | Q9: OFICIAL | R9: AFORO PERMANENTE | S9: Ocupado | T9: 2026 | U9: 5 | V9: 1081522159 | W9: 1081540229 | X9: 08-05-2026 | Y9: 03-06-2026 | Z9: 5359534.4 | AA9: 5359534.4 | AB9: 0 | AC9: 113880 | AD9: 0 | AE9: 0 | AF9: 0 | AG9: 0 | AH9: 0 | AI9: 5359534.4 | AJ9: 5359534.4 | AK9: 0 | AL9: 1560725.4 | AM9: 0 | AR9: 0 | AS9: tesoreria@sancayetano-nortedesantander.gov.co | AT9: CORREO ELECTRONICO CERTIFICADO 472 | AU9: ANGEL | AV9: 46170
A10: 2760 | B10: 2759 | C10: 2759 | D10: 90290491 | E10: 90290491 | F10: 901238264-9 | G10: ADM PUB SERV PUBL DOMICILIA ACU ALC ASEO | H10: CRA 5 6-03 BARR PERPETUO SOCORRO | I10: HERRAN | J10: DF | K10: DF | L10: CÚCUTA MPO | M10: CUCUTA ZONA SUR | N10: 1001 - CICL FACT PARQUE GUAYABAL( 63) | O10: DIS. FINAL Y TRATAMIENTO | P10: NO RESIDENCIAL - ASEO GP | Q10: INDUSTRIAL | R10: AFORO PERMANENTE | S10: Ocupado | T10: 2026 | U10: 5 | V10: 1081522162 | W10: 1081540232 | X10: 08-05-2026 | Y10: 03-06-2026 | Z10: 693708.62 | AA10: 693708.62 | AB10: 0 | AC10: 14740 | AD10: 0 | AE10: 0 | AF10: 0 | AG10: 0 | AH10: 0 | AI10: 693708.62 | AJ10: 1276819.2 | AK10: 1 | AL10: 202011.7 | AM10: 0 | AR10: 0 | AS10: APCMANOBAHERRAN@GMAIL.COM | AT10: CORREO ELECTRONICO CERTIFICADO 472 | AU10: ANGEL | AV10: 46171
A11: 369348 | B11: 362075 | C11: 365048 | F11: 901085013 | G11: IBEROAMERICANA DE HIDROCARBUROS ENERGY COLOMBIA S.A.S | H11: #N/A | I11: #N/A | J11: DF | K11: DF | L11: CÚCUTA MPO | M11: CUCUTA DIRECTA | N11: 1001 - CICL FACT PARQUE GUAYABAL( 63) | O11: DIS. FINAL Y TRATAMIENTO | P11: NO RESIDENCIAL - ASEO GP | Q11: INDUSTRIAL | R11: AFORO PERMANENTE | S11: Ocupado | T11: 2026 | U11: 5 | V11: 1081522165 | W11: 1081540235 | X11: 08-05-2026 | Y11: 03-06-2026 | Z11: 21666.84 | AA11: 21666.84 | AB11: 0 | AC11: 510 | AD11: 0 | AE11: 0 | AF11: 0 | AG11: 0 | AH11: 0 | AI11: 21666.84 | AJ11: 21666.84 | AK11: 0 | AL11: 4654.26 | AM11: 0 | AR11: 0 | AS11: FROJAS@IHSAENERGY.CO | AT11: CORREO ELECTRONICO CERTIFICADO 472 | AU11: ANGEL | AV11: 46171
A12: 584 | B12: 583 | C12: 583 | D12: 90275668 | E12: 90275668 | F12: 807005252-1 | G12: ECOAMBIENTAL DEL NORTE SAS ESP | H12: CARRERA 7 NO. 3-17 VILLA DEL ROSARIO | I12: SIN DETERMINAR | J12: DF | K12: DF | L12: CÚCUTA MPO | M12: CUCUTA ZONA SUR | N12: 1001 - CICL FACT PARQUE GUAYABAL( 63) | O12: DIS. FINAL Y TRATAMIENTO | P12: NO RESIDENCIAL - ASEO GP | Q12: INDUSTRIAL | R12: AFORO PERMANENTE | S12: Ocupado | T12: 2026 | U12: 5 | V12: 1081522140 | W12: 1081540210 | X12: 08-05-2026 | Y12: 03-06-2026 | Z12: 10810600 | AA12: 10810600 | AB12: 0 | AC12: 227270 | AD12: 114592.31 | AE12: 0 | AF12: 0 | AG12: 0 | AH12: 0 | AI12: 10810600 | AJ12: 22153268 | AK12: 2 | AL12: 3114735.4 | AM12: 0 | AR12: 0 | AS12: ecoambiental807@gmail.com | AT12: CORREO ELECTRONICO CERTIFICADO 472 | AU12: ANGEL | AV12: 46171
A13: 2742 | B13: 2741 | C13: 2741 | D13: 90254686 | E13: 90254686 | F13: 807000581-5 | G13: EMPRESAS PUBLICAS MUNICIPALES DE CHINACOTA EMCHINAC | H13: CRA 4A 13-35 BARRIO LAS COLINAS/CHINACOTA | I13: 0 | J13: NO | K13: DF | L13: CÚCUTA MPO | M13: CUCUTA ZONA SUR | N13: 1001 - CICL FACT PARQUE GUAYABAL( 63) | O13: DIS. FINAL Y TRATAMIENTO | P13: NO RESIDENCIAL - ASEO GP | Q13: INDUSTRIAL | R13: AFORO PERMANENTE | S13: Ocupado | T13: 2026 | U13: 5 | V13: 1081522139 | W13: 1081540209 | X13: 08-05-2026 | Y13: 03-06-2026 | Z13: 13292790 | AA13: 13292790 | AB13: 0 | AC13: 281990 | AD13: 21494.15 | AE13: 0 | AF13: 0 | AG13: 0 | AH13: 0 | AI13: 13292790 | AJ13: 13292790 | AK13: 0 | AL13: 3864673 | AM13: 0 | AR13: 0 | AS13: EMCHINAC@EMCHINACESP-CHINACOTA.GOV.CO | AT13: CORREO ELECTRONICO CERTIFICADO 472 | AU13: ANGEL | AV13: 46170
A14: 2746 | B14: 2745 | C14: 2745 | D14: 90256586 | E14: 90256586 | F14: 800099251 | G14: ALCALDIA MUNICIPIO RAGONVALIA | H14: CALLE 6 NO. 2-32 | I14: 0 | J14: NO | K14: DF | L14: CÚCUTA MPO | M14: CUCUTA ZONA SUR | N14: 1001 - CICL FACT PARQUE GUAYABAL( 63) | O14: DIS. FINAL Y TRATAMIENTO | P14: NO RESIDENCIAL - ASEO GP | Q14: OFICIAL | R14: AFORO PERMANENTE | S14: Ocupado | T14: 2026 | U14: 5 | V14: 1081522143 | W14: 1081540213 | X14: 08-05-2026 | Y14: 03-06-2026 | Z14: 1375180.9 | AA14: 1375180.9 | AB14: 0 | AC14: 29220 | AD14: 0 | AE14: 0 | AF14: 0 | AG14: 0 | AH14: 0 | AI14: 1375180.9 | AJ14: 3283114.9 | AK14: 1 | AL14: 400460.1 | AM14: 0 | AR14: 0 | AS14: HACIENDA@RAGONVALIA-NORTEDESANTANDER.GOV.CO | AT14: CORREO ELECTRONICO CERTIFICADO 472 | AU14: ANGEL | AV14: 46170
A15: 2750 | B15: 2749 | C15: 2749 | D15: 90257708 | E15: 90257708 | F15: 890501981 | G15: MUNICIPIO DE VILLA CARO | H15: PALACIO MPAL VILLA CARO | I15: 0 | J15: NO | K15: DF | L15: CÚCUTA MPO | M15: CUCUTA ZONA SUR | N15: 1001 - CICL FACT PARQUE GUAYABAL( 63) | O15: DIS. FINAL Y TRATAMIENTO | P15: NO RESIDENCIAL - ASEO GP | Q15: OFICIAL | R15: AFORO PERMANENTE | S15: Ocupado | T15: 2026 | U15: 5 | V15: 1081522149 | W15: 1081540219 | X15: 08-05-2026 | Y15: 03-06-2026 | Z15: 804306.67 | AA15: 804306.67 | AB15: 0 | AC15: 17090 | AD15: 0 | AE15: 0 | AF15: 0 | AG15: 0 | AH15: 0 | AI15: 804306.67 | AJ15: 804306.67 | AK15: 0 | AL15: 234218.45 | AM15: 0 | AR15: 0 | AS15: tesoreria@villacaro-nortedesantander.gov.co | AT15: CORREO ELECTRONICO CERTIFICADO 472 | AU15: ANGEL | AV15: 46170
A16: 2758 | B16: 2757 | C16: 2757 | D16: 90267356 | E16: 90267356 | F16: 890501436-7 | G16: ALCALDIA MUNICIPIO DE ARBOLEDAS | H16: CRA 6 CALLE 2 Y 3 NO 6-25 | I16: 0 | J16: NO | K16: DF | L16: CÚCUTA MPO | M16: CUCUTA ZONA SUR | N16: 1001 - CICL FACT PARQUE GUAYABAL( 63) | O16: DIS. FINAL Y TRATAMIENTO | P16: NO RESIDENCIAL - ASEO GP | Q16: OFICIAL | R16: AFORO PERMANENTE | S16: Ocupado | T16: 2026 | U16: 5 | V16: 1081522153 | W16: 1081540223 | X16: 08-05-2026 | Y16: 03-06-2026 | Z16: 2025120.9 | AA16: 2025120.9 | AB16: 0 | AC16: 43030 | AD16: 0 | AE16: 0 | AF16: 0 | AG16: 0 | AH16: 0 | AI16: 2025120.9 | AJ16: 2025121.8 | AK16: 1 | AL16: 589726.15 | AM16: 0 | AR16: 0 | AS16: tesoreria@arboledas-nortedesantander.gov.co | AT16: CORREO ELECTRONICO CERTIFICADO 472 | AU16: ANGEL | AV16: 46170
A17: 608069 | B17: 502777 | C17: 558548 | F17: 900508526 | G17: EMPRESA DE SOLUCIONES AMBIENTALES PARA COLOMBIA S.A.S E.S.P | H17: KM 7 VDA EL CUCHARO | I17: #N/A | J17: DF | K17: DF | L17: CÚCUTA MPO | M17: CUCUTA DIRECTA | N17: 1001 - CICL FACT PARQUE GUAYABAL( 63) | O17: DIS. FINAL Y TRATAMIENTO | P17: NO RESIDENCIAL - ASEO GP | Q17: COMERCIAL | R17: NO AFORADO | S17: Ocupado | T17: 2026 | U17: 5 | V17: 1081523254 | W17: 1081541324 | X17: 08-05-2026 | Y17: 03-06-2026 | Z17: 2144661 | AA17: 2144661 | AB17: 0 | AC17: 0 | AD17: 0 | AE17: 0 | AF17: 0 | AG17: 0 | AH17: 0 | AI17: 2144661 | AJ17: 2144661 | AK17: 0 | AL17: 624537 | AM17: 0 | AR17: 0 | AS17: empsacol@hotmail.com | AT17: CORREO ELECTRONICO CERTIFICADO 472 | AU17: ANGEL | AV17: 46171
A18: 2293 | B18: 2292 | C18: 2292 | D18: 90265701 | E18: 90265701 | F18: 890501301-1 | G18: SOCIEDAD MEJORAS PUBLICAS DE CUCUTA | H18: CALLE 4AN # 4-89 PESCADERO | I18: PESCADERO | J18: NO | K18: DF | L18: CÚCUTA MPO | M18: CUCUTA DIRECTA | N18: 1001 - CICL FACT PARQUE GUAYABAL( 63) | O18: DIS. FINAL Y TRATAMIENTO | P18: NO RESIDENCIAL - ASEO GP | Q18: INDUSTRIAL | R18: AFORO PERMANENTE | S18: Ocupado | T18: 2026 | U18: 5 | V18: 1081522144 | W18: 1081540214 | X18: 08-05-2026 | Y18: 03-06-2026 | Z18: 4131569 | AA18: 4131569 | AB18: 0 | AC18: 97250 | AD18: 0 | AE18: 0 | AF18: 0 | AG18: 0 | AH18: 0 | AI18: 4131569 | AJ18: 4131569 | AK18: 0 | AL18: 887503.5 | AM18: 0 | AR18: 0 | AS18: contacto@smpcucuta.com | AT18: CORREO ELECTRONICO CERTIFICADO 472 | AU18: ANGEL | AV18: 46170
A19: 2741 | B19: 2740 | C19: 2740 | D19: 90253728 | E19: 90253728 | F19: 800250853-1 | G19: ALCALDIA MUNICIPAL PUERTO SANT | H19: CARERA 2 NO. 2-35 | I19: 0 | J19: NO | K19: DF | L19: CÚCUTA MPO | M19: CUCUTA ZONA SUR | N19: 1001 - CICL FACT PARQUE GUAYABAL( 63) | O19: DIS. FINAL Y TRATAMIENTO | P19: NO RESIDENCIAL - ASEO GP | Q19: OFICIAL | R19: AFORO PERMANENTE | S19: Ocupado | T19: 2026 | U19: 5 | V19: 1081522147 | W19: 1081540217 | X19: 08-05-2026 | Y19: 03-06-2026 | Z19: 4748186.1 | AA19: 4748186.1 | AB19: 0 | AC19: 100890 | AD19: 0 | AE19: 0 | AF19: 0 | AG19: 0 | AH19: 0 | AI19: 4748186.1 | AJ19: 4748186.1 | AK19: 0 | AL19: 1382697.4 | AM19: 0 | AR19: 0 | AS19: TESORERIA@PUERTOSANTANDER-NORTEDESANTANDER.GOV.CO | AT19: CORREO ELECTRONICO CERTIFICADO 472 | AU19: ANGEL | AV19: 46170
A20: 2745 | B20: 2744 | C20: 2744 | D20: 90256525 | E20: 90256525 | F20: 800099263-8 | G20: MUNICIPIO DE SARDINATA | H20: CALLE 6 NO. 6 55 CENTRO SARDINATA | I20: 0 | J20: NO | K20: DF | L20: CÚCUTA MPO | M20: CUCUTA ZONA SUR | N20: 1001 - CICL FACT PARQUE GUAYABAL( 63) | O20: DIS. FINAL Y TRATAMIENTO | P20: NO RESIDENCIAL - ASEO GP | Q20: OFICIAL | R20: AFORO PERMANENTE | S20: Ocupado | T20: 2026 | U20: 5 | V20: 1081522152 | W20: 1081540222 | X20: 08-05-2026 | Y20: 03-06-2026 | Z20: 10621178 | AA20: 10621178 | AB20: 0 | AC20: 225680 | AD20: 0 | AE20: 0 | AF20: 0 | AG20: 0 | AH20: 0 | AI20: 10621178 | AJ20: 32110854 | AK20: 2 | AL20: 3092944.4 | AM20: 0 | AR20: 0 | AT20: CORREO ELECTRONICO CERTIFICADO 472 | AU20: ANGEL | AV20: 46170
A21: 2749 | B21: 2748 | C21: 2748 | D21: 90257658 | E21: 90257658 | F21: 890501549 | G21: MPIO DE SALAZAR DE LAS PALMAS | H21: CALLE 2 CARRERA 6 ESQUINA | I21: 0 | J21: NO | K21: DF | L21: CÚCUTA MPO | M21: CUCUTA ZONA SUR | N21: 1001 - CICL FACT PARQUE GUAYABAL( 63) | O21: DIS. FINAL Y TRATAMIENTO | P21: NO RESIDENCIAL - ASEO GP | Q21: INDUSTRIAL | R21: AFORO PERMANENTE | S21: Ocupado | T21: 2026 | U21: 5 | V21: 1081522156 | W21: 1081540226 | X21: 08-05-2026 | Y21: 03-06-2026 | Z21: 3614909 | AA21: 3614909 | AB21: 0 | AC21: 76810 | AD21: 0 | AE21: 0 | AF21: 0 | AG21: 0 | AH21: 0 | AI21: 370867.61 | AJ21: 370867.61 | AK21: 0 | AL21: 1052681.1 | AM21: 0 | AP21: 3244041.4 | AR21: 0 | AS21: HACIENDA@SALAZARDELASPALMAS-NORTEDESANTANDER.GOV.CO | AT21: CORREO ELECTRONICO CERTIFICADO 472 | AU21: ANGEL | AV21: 46170
A22: 2753 | B22: 2752 | C22: 2752 | D22: 90257711 | E22: 90257711 | F22: 807002043 | G22: EMZULIA E.S.P | H22: CLL 7 NO 2-03 BARRIO CENTRO MUNICIPIO EL ZULIA | I22: 0 | J22: NO | K22: DF | L22: CÚCUTA MPO | M22: CUCUTA ZONA SUR | N22: 1001 - CICL FACT PARQUE GUAYABAL( 63) | O22: DIS. FINAL Y TRATAMIENTO | P22: NO RESIDENCIAL - ASEO GP | Q22: INDUSTRIAL | R22: AFORO PERMANENTE | S22: Ocupado | T22: 2026 | U22: 5 | V22: 1081522160 | W22: 1081540230 | X22: 08-05-2026 | Y22: 03-06-2026 | Z22: 21318598 | AA22: 21318598 | AB22: 0 | AC22: 452980 | AD22: 0 | AE22: 0 | AF22: 0 | AG22: 0 | AH22: 0 | AI22: 21318598 | AJ22: 21318598 | AK22: 0 | AL22: 6208090.9 | AM22: 0 | AR22: 0 | AS22: emzulia.esp@gmail.com | AT22: CORREO ELECTRONICO CERTIFICADO 472 | AU22: ANGEL | AV22: 46170
A23: 2757 | B23: 2756 | C23: 2756 | D23: 90257826 | E23: 90257826 | F23: 890505662 | G23: MUNICIPIO DE BOCHALEMA | H23: CALLE 3 NO 3 - 08 | I23: 0 | J23: NO | K23: DF | L23: CÚCUTA MPO | M23: CUCUTA ZONA SUR | N23: 1001 - CICL FACT PARQUE GUAYABAL( 63) | O23: DIS. FINAL Y TRATAMIENTO | P23: NO RESIDENCIAL - ASEO GP | Q23: OFICIAL | R23: AFORO PERMANENTE | S23: Ocupado | T23: 2026 | U23: 5 | V23: 1081522163 | W23: 1081540233 | X23: 08-05-2026 | Y23: 03-06-2026 | Z23: 4599467 | AA23: 4599467 | AB23: 0 | AC23: 97730 | AD23: 0 | AE23: 0 | AF23: 0 | AG23: 0 | AH23: 0 | AI23: 4599467 | AJ23: 4599467.3 | AK23: 1 | AL23: 1339389.6 | AM23: 0 | AR23: 0 | AS23: UNISEPUBLICOS@BOCHALEMA-NORTEDESANTANDER.GOV.CO | AT23: CORREO ELECTRONICO CERTIFICADO 472 | AU23: ANGEL | AV23: 46170
A24: 433 | B24: 432 | C24: 432 | D24: 90253757 | E24: 90253757 | F24: 901347799 | G24: CURTIEMBRES CUCUTA SAS NIT.901.347.799-4 | H24: KM 6 #49-40 VIA SAUFASTINO EL SERRITO | I24: SIN DETERMINAR | J24: NO | K24: DF | L24: CÚCUTA MPO | M24: CUCUTA ZONA SUR | N24: 1001 - CICL FACT PARQUE GUAYABAL( 63) | O24: DIS. FINAL Y TRATAMIENTO | P24: NO RESIDENCIAL - ASEO GP | Q24: INDUSTRIAL | R24: AFORO PERMANENTE | S24: Ocupado | T24: 2026 | U24: 5 | V24: 1081522135 | W24: 1081540205 | X24: 08-05-2026 | Y24: 03-06-2026 | Z24: 849255.16 | AA24: 849255.16 | AB24: 0 | AC24: 19990 | AD24: 0 | AE24: 0 | AF24: 0 | AG24: 0 | AH24: 0 | AI24: 849255.16 | AJ24: 849255.16 | AK24: 0 | AL24: 182428.74 | AM24: 0 | AR24: 0 | AS24: CURTIEMBRESCUCUTA@GMAIL.COM | AT24: CORREO ELECTRONICO CERTIFICADO 472 | AU24: ANGEL | AV24: 46170
A25: 505 | B25: 504 | C25: 504 | D25: 90268059 | E25: 90268059 | F25: 60366490 | G25: NATALIA ANDREA ROJAS | H25: CLL 21 0E- 20 CAOBOS | I25: BARRIO BLANCO | J25: NO | K25: DF | L25: CÚCUTA MPO | M25: CUCUTA DIRECTA | N25: 1001 - CICL FACT PARQUE GUAYABAL( 63) | O25: DIS. FINAL Y TRATAMIENTO | P25: NO RESIDENCIAL - ASEO GP | Q25: INDUSTRIAL | R25: AFORO PERMANENTE | S25: Ocupado | T25: 2026 | U25: 5 | V25: 1081522138 | W25: 1081540208 | X25: 08-05-2026 | Y25: 03-06-2026 | Z25: 799606.96 | AA25: 799606.96 | AB25: 0 | AC25: 17780 | AD25: 44241.44 | AE25: 0 | AF25: 0 | AG25: 0 | AH25: 0 | AI25: 799606.96 | AJ25: 3608549.1 | AK25: 4 | AL25: 162260.28 | AM25: 0 | AR25: 0 | AS25: NAROHE10@HOTMAIL.COM | AT25: CORREO ELECTRONICO CERTIFICADO 472 | AU25: ANGEL | AV25: 46171
A26: 125141 | B26: 125140 | C26: 125140 | D26: 590301 | E26: 590301 | F26: 890104633-9 | G26: UNIVERSIDAD SIMON BOLIVAR-OTROS | H26: AVE 3 # 13-82 | I26: LA PLAYA | J26: NO | K26: NO | L26: CÚCUTA MPO | M26: CUCUTA DIRECTA | N26: 1002 - CICL FACT DIRECTA CUCUTA NORTE | O26: ASEO INTEGRAL | P26: NO RESIDENCIAL - ASEO PP | Q26: COMERCIAL RANGO 3 | R26: NO AFORADO | S26: Ocupado | T26: 2026 | U26: 5 | V26: 1081522458 | W26: 1081540528 | X26: 08-05-2026 | Y26: 03-06-2026 | Z26: 114427.12 | AA26: 114427.12 | AB26: 37970.5 | AC26: 0 | AD26: 515.62 | AE26: 0 | AF26: 0 | AG26: 0 | AH26: 0 | AI26: 114427.12 | AJ26: 114427.12 | AK26: 0 | AL26: 376.2 | AM26: 0 | AR26: 0 | AS26: facturaelectronicacucuta@unisimon.edu.co; 890104633_201@FACTURENINBOX.CO | AT26: CORREO ELECTRONICO CERTIFICADO 472 | AU26: Liliana | AV26: 46167
